#VRML_SIM R2025a utf8

EXTERNPROTO "https://raw.githubusercontent.com/cyberbotics/webots/R2025a/projects/objects/backgrounds/protos/TexturedBackground.proto"
EXTERNPROTO "https://raw.githubusercontent.com/cyberbotics/webots/R2025a/projects/objects/backgrounds/protos/TexturedBackgroundLight.proto"
EXTERNPROTO "https://raw.githubusercontent.com/cyberbotics/webots/R2025a/projects/objects/floors/protos/RectangleArena.proto"

WorldInfo {
}
Viewpoint {
  orientation 0.6299156227463598 0.11263504873705733 -0.7684527662882519 2.868484706001857
  position 1.4150942538897802 0.3929372091493106 6.782323584577964
}
TexturedBackground {
}
TexturedBackgroundLight {
}
RectangleArena {
  floorSize 2 2
  floorAppearance PBRAppearance {
    roughness 1
    roughnessMap ImageTexture {
      url [
        "https://raw.githubusercontent.com/cyberbotics/webots/R2023b/projects/appearances/protos/textures/parquetry/mosaic_parquetry_roughness.jpg"
      ]
    }
    metalness 0
    normalMap ImageTexture {
      url [
        "https://raw.githubusercontent.com/cyberbotics/webots/R2023b/projects/appearances/protos/textures/parquetry/mosaic_parquetry_normal.jpg"
      ]
    }
    occlusionMap ImageTexture {
      url [
        "https://raw.githubusercontent.com/cyberbotics/webots/R2023b/projects/appearances/protos/textures/parquetry/mosaic_parquetry_occlusion.jpg"
      ]
    }
  }
}
Solid {
  translation 0.45 -0.73 0.05
  rotation 0 0 -1 -0.13090030610042527
  children [
    DEF obstacle1 Shape {
      appearance PBRAppearance {
        baseColor 0 0 0
        roughness 1
        metalness 0
      }
      geometry Box {
        size 0.1 0.1 0.1
      }
    }
  ]
  boundingObject USE obstacle1
  locked TRUE
}
Solid {
  translation 0.666748 -0.198009 0.05
  rotation 0 0 -1 -1.3089953071795861
  children [
    DEF obstacle2 Shape {
      appearance PBRAppearance {
        baseColor 0 0 0
        roughness 1
        metalness 0
      }
      geometry Box {
        size 0.2 0.1 0.1
      }
    }
  ]
  name "solid(1)"
  boundingObject USE obstacle2
  locked TRUE
}
Solid {
  translation 0.36358 0.381911 0.05
  rotation 0 0 -1 -1.047195307179586
  children [
    DEF obstacle3 Shape {
      appearance PBRAppearance {
        baseColor 0 0 0
        roughness 1
        metalness 0
      }
      geometry Box {
        size 0.12 0.1 0.1
      }
    }
  ]
  name "solid(3)"
  boundingObject USE obstacle3
  locked TRUE
}
Solid {
  translation -0.380764 0.661551 0.05
  rotation 0 0 1 2.09439
  children [
    DEF obstacle4 Shape {
      appearance PBRAppearance {
        baseColor 0 0 0
        roughness 1
        metalness 0
      }
      geometry Box {
        size 0.12 0.1 0.1
      }
    }
  ]
  name "solid(4)"
  boundingObject USE obstacle4
  locked TRUE
}
Solid {
  translation -0.545793 -0.0756207 0.05
  rotation 0 0 1 1.83259
  children [
    DEF obstacle5 Shape {
      appearance PBRAppearance {
        baseColor 0 0 0
        roughness 1
        metalness 0
      }
      geometry Box {
        size 0.1 0.3 0.1
      }
    }
  ]
  name "solid(5)"
  boundingObject USE obstacle5
  locked TRUE
}
Solid {
  translation -0.356546 -0.527723 0
  rotation 0 0 1 2.8797896938995744
  children [
    Shape {
      appearance PBRAppearance {
        baseColor 1 0 0
        roughness 1
        metalness 0
      }
      geometry Box {
        size 0.03 0.51 0.0005
      }
    }
  ]
  name "solid(6)"
  locked TRUE
}
Solid {
  children [
    Shape {
      appearance PBRAppearance {
        baseColor 0 0 0
        roughness 1
        metalness 0
      }
      geometry Mesh {
        url [
          "../path/outer_path.obj"
        ]
      }
    }
  ]
  name "solid(2)"
  boundingObject Mesh {
    url [
      "../path/outer_path.obj"
    ]
  }
  locked TRUE
}
Solid {
  children [
    Shape {
      appearance PBRAppearance {
        baseColor 0 0 0
        roughness 1
        metalness 0
      }
      geometry Mesh {
        url [
          "../path/inner_path.obj"
        ]
      }
    }
  ]
  name "solid(7)"
  boundingObject Mesh {
    url [
      "../path/inner_path.obj"
    ]
  }
  locked TRUE
}
Robot {
  translation -0.115005 -0.513655 0.0218477
  rotation -0.5290632847796215 0.5911832078591351 0.6087646962855022 -2.1436099385522143
  children [
    Lidar {
      translation 2.67257e-05 0.0299963 0.000272275
      rotation 0.5030470370970558 0.6020562948954822 0.6200579781315597 -2.19
      name "lidar(1)"
      type "rotating"
    }
    Pose {
      children [
        DEF body Shape {
          appearance PBRAppearance {
            baseColor 0.5 0.6 1
          }
          geometry Box {
            size 0.1 0.04 0.16
          }
        }
      ]
    }
    Pose {
      translation 0 0 0.08
      children [
        Lidar {
          translation 0 0 0.08
          rotation 0 1 0 0
          horizontalResolution 1
          fieldOfView 6.28319
          numberOfLayers 1
          maxRange 5
          type "rotating"
          noise 0.01
          resolution 512
        }
        Shape {
          appearance PBRAppearance {
            baseColor 0.8 0.8 0.8
          }
          geometry Cylinder {
            height 0.02
            radius 0.02
          }
        }
      ]
    }
    HingeJoint {
      jointParameters HingeJointParameters {
        position 33.40538726435905
        anchor 0.0598 -0.017 -0.05
      }
      device [
        RotationalMotor {
          name "left_motor"
          maxTorque 0.1
        }
        PositionSensor {
          name "left_encoder"
          resolution 0.01
        }
      ]
      endPoint Solid {
        translation 0.0598 -0.017 -0.05
        rotation -0.6425687620912118 0.4173866480323335 0.6425681069185589 3.9324022546473287
        children [
          DEF wheel Shape {
            appearance PBRAppearance {
              baseColor 1 0 0
              roughness 1
              metalness 0
            }
            geometry Cylinder {
              height 0.02
              radius 0.02
            }
          }
        ]
        boundingObject USE wheel
        physics Physics {
          mass 0.05
        }
      }
    }
    HingeJoint {
      jointParameters HingeJointParameters {
        position 21.342179670347573
        anchor -0.0598 -0.017 -0.05
      }
      device [
        RotationalMotor {
          name "right_motor"
          maxTorque 0.1
        }
        PositionSensor {
          name "right_encoder"
          resolution 0.01
        }
      ]
      endPoint Solid {
        translation -0.0598 -0.017 -0.05
        rotation -0.6879158973575922 0.23139663209725014 0.6879151959484167 3.5963819912774735
        children [
          USE wheel
        ]
        boundingObject USE wheel
        physics Physics {
          mass 0.05
        }
      }
    }
    BallJoint {
      jointParameters BallJointParameters {
        position -37.28491831885926
        anchor 0 -0.03 0.05
      }
      endPoint Solid {
        translation 8.303557901946957e-07 -0.02999332617910881 0.05000088907971886
        rotation 0.5798147209403128 0.5188417728553497 -0.6281863609799441 1.2991023936550707
        children [
          DEF caster Shape {
            appearance PBRAppearance {
              baseColor 0 0 0
              roughness 1
              metalness 0
            }
            geometry Sphere {
              radius 0.01
            }
          }
        ]
        boundingObject USE caster
        physics Physics {
        }
      }
    }
  ]
  boundingObject USE body
  physics Physics {
    mass 0.3
  }
  controller "my_controller"
}
