#VRML_SIM R2025a utf8
EXTERNPROTO "https://raw.githubusercontent.com/cyberbotics/webots/R2025a/projects/objects/backgrounds/protos/TexturedBackground.proto"
EXTERNPROTO "https://raw.githubusercontent.com/cyberbotics/webots/R2025a/projects/objects/backgrounds/protos/TexturedBackgroundLight.proto"

WorldInfo {
}
Viewpoint {
  orientation 0.3683835930923153 -0.1666962430903363 -0.9146069597810653 3.926390205552976
  position 2.134515286674531 -2.166986268926602 2.235059093837157
}
TexturedBackground {
}
TexturedBackgroundLight {
}
RectangleArena {
  floorSize 2 2
  floorAppearance PBRAppearance {
    roughness 1
    roughnessMap ImageTexture {
      url [
        "https://raw.githubusercontent.com/cyberbotics/webots/R2023b/projects/appearances/protos/textures/parquetry/mosaic_parquetry_roughness.jpg"
      ]
    }
    metalness 0
    normalMap ImageTexture {
      url [
        "https://raw.githubusercontent.com/cyberbotics/webots/R2023b/projects/appearances/protos/textures/parquetry/mosaic_parquetry_normal.jpg"
      ]
    }
    occlusionMap ImageTexture {
      url [
        "https://raw.githubusercontent.com/cyberbotics/webots/R2023b/projects/appearances/protos/textures/parquetry/mosaic_parquetry_occlusion.jpg"
      ]
    }
  }
}
Solid {
  translation 0.45 -0.73 0.05
  rotation 0 0 -1 -0.13090030610042527
  children [
    DEF obstacle1 Shape {
      appearance PBRAppearance {
        baseColor 0 0 0
        roughness 1
        metalness 0
      }
      geometry Box {
        size 0.1 0.1 0.1
      }
    }
  ]
  boundingObject USE obstacle1
  locked TRUE
}
Solid {
  translation 0.666748 -0.198009 0.05
  rotation 0 0 -1 -1.3089953071795861
  children [
    DEF obstacle2 Shape {
      appearance PBRAppearance {
        baseColor 0 0 0
        roughness 1
        metalness 0
      }
      geometry Box {
        size 0.2 0.1 0.1
      }
    }
  ]
  name "solid(1)"
  boundingObject USE obstacle2
  locked TRUE
}
Solid {
  translation 0.36358 0.381911 0.05
  rotation 0 0 -1 -1.047195307179586
  children [
    DEF obstacle3 Shape {
      appearance PBRAppearance {
        baseColor 0 0 0
        roughness 1
        metalness 0
      }
      geometry Box {
        size 0.12 0.1 0.1
      }
    }
  ]
  name "solid(3)"
  boundingObject USE obstacle3
  locked TRUE
}
Solid {
  translation -0.380764 0.661551 0.05
  rotation 0 0 1 2.09439
  children [
    DEF obstacle4 Shape {
      appearance PBRAppearance {
        baseColor 0 0 0
        roughness 1
        metalness 0
      }
      geometry Box {
        size 0.12 0.1 0.1
      }
    }
  ]
  name "solid(4)"
  boundingObject USE obstacle4
  locked TRUE
}
Solid {
  translation -0.545793 -0.0756207 0.05
  rotation 0 0 1 1.83259
  children [
    DEF obstacle5 Shape {
      appearance PBRAppearance {
        baseColor 0 0 0
        roughness 1
        metalness 0
      }
      geometry Box {
        size 0.1 0.3 0.1
      }
    }
  ]
  name "solid(5)"
  boundingObject USE obstacle5
  locked TRUE
}
Solid {
  translation -0.356546 -0.527723 0
  rotation 0 0 1 2.8797896938995744
  children [
    Shape {
      appearance PBRAppearance {
        baseColor 1 0 0
        roughness 1
        metalness 0
      }
      geometry Box {
        size 0.03 0.51 0.0005
      }
    }
  ]
  name "solid(6)"
  locked TRUE
}
Solid {
  children [
    Shape {
      appearance PBRAppearance {
        baseColor 0 0 0
        roughness 1
        metalness 0
      }
      geometry Mesh {
        url [
          "../path/outer_path.obj"
        ]
      }
    }
  ]
  name "solid(2)"
  boundingObject Mesh {
    url [
      "../path/outer_path.obj"
    ]
  }
  locked TRUE
}
Solid {
  children [
    Shape {
      appearance PBRAppearance {
        baseColor 0 0 0
        roughness 1
        metalness 0
      }
      geometry Mesh {
        url [
          "../path/inner_path.obj"
        ]
      }
    }
  ]
  name "solid(7)"
  boundingObject Mesh {
    url [
      "../path/inner_path.obj"
    ]
  }
  locked TRUE
}
Robot {
  translation -0.30991533159298706 -0.5228428971341005 0.03831670154955861
  rotation -0.503292108654829 0.6022379124370137 0.6196826205319005 -2.1859645493653757
  children [
    Pose {
      children [
        DEF body Shape {
          appearance PBRAppearance {
            baseColor 0.5 0.6 1
          }
          geometry Box {
            size 0.1 0.04 0.16
          }
        }
      ]
    }
    # Visualized Lidar
    Pose {
      translation 0 0 0.08
      children [
        DEF lidar Lidar {
          translation 0 0 0.08
          rotation 0 1 0 0
          locked TRUE
          horizontalResolution 1
          fieldOfView 6.28319
          numberOfLayers 1
          maxRange 5
          type "rotating"
          noise 0.01
          resolution 512
        }
        Shape {
          appearance PBRAppearance {
            baseColor 0 1 1  # Cyan Lidar
            roughness 1
          }
          geometry Cylinder {
            height 0.02
            radius 0.015
          }
        }
      ]
    }

      ]
    }
    Gyro {
    }
    Accelerometer {
    }
    Compass {
    }
    HingeJoint {
      jointParameters HingeJointParameters {
        position 12.06320894724401
        anchor 0.0598 -0.017 -0.05
      }
      device [
        RotationalMotor {
          name "left_motor"
          maxTorque 0.1
        }
        PositionSensor {
          name "left_encoder"
          resolution 0.01
        }
      ]
      endPoint Solid {
        translation 0.0598 -0.017 -0.05
        rotation -0.2415633761644221 -0.9398374272111742 0.24156312986283035 1.6328039014986284
        children [
          DEF wheel Shape {
            appearance PBRAppearance {
              baseColor 1 0 0
              roughness 1
              metalness 0
            }
            geometry Cylinder {
              height 0.02
              radius 0.02
            }
          }
        ]
        boundingObject USE wheel
        physics Physics {
          mass 0.05
        }
        linearVelocity -0.009138718023340922 0.0016471390234034297 3.455722265584425e-05
        angularVelocity -0.08847568120670744 -0.49197832876451403 -0.07174251768443846
      }
    }
    HingeJoint {
      jointParameters HingeJointParameters {
        position 1.180793159991712e-06
        anchor -0.0598 -0.017 -0.05
      }
      device [
        RotationalMotor {
          name "right_motor"
          maxTorque 0.1
        }
        PositionSensor {
          name "right_encoder"
          resolution 0.01
        }
      ]
      endPoint Solid {
        translation -0.0598 -0.017 -0.05
        rotation 5.90397181973418e-07 -0.9999999999996514 -5.903965799957189e-07 1.5707953071799345
        children [
          USE wheel
        ]
        boundingObject USE wheel
        physics Physics {
          mass 0.05
        }
        linearVelocity -0.000697762573255042 0.00012710729021259137 1.972188788636542e-06
        angularVelocity -0.0002330171225376595 0.0001735562846755076 -0.07168935489698222
      }
    }
    BallJoint {
      jointParameters BallJointParameters {
        position 0.2464666855364956
        anchor 0 -0.03 0.05
      }
      endPoint Solid {
        translation -4.661482977397213e-08 -0.029997953043481688 0.05000099947682035
        rotation 0.9155629488561119 -0.1562530353317831 -0.37057991800892964 1.0991063734270028
        children [
          DEF caster Shape {
            appearance PBRAppearance {
              baseColor 0 0 0
              roughness 1
              metalness 0
            }
            geometry Sphere {
              radius 0.01
            }
          }
        ]
        boundingObject USE caster
        physics Physics {
        }
        linearVelocity -0.00364690594919514 0.007962495723202897 3.272762395692507e-05
        angularVelocity -0.796249571861598 -0.36469059581027874 1.0347002864571453
      }
    }
     DistanceSensor {
      translation 0.05 0 0.08
      rotation 0 1 0 -0.3
      name "ds_right"
      lookupTable [
        0 0 0
        0.8 800 0
      ]
    }
    DistanceSensor {
      translation -0.05 0 0.08
      rotation 0 1 0 0.3
      name "ds_left"
      lookupTable [
        0 0 0
        0.8 800 0
      ]
    }
      ]
    }
  ]
  boundingObject USE body
  physics Physics {
    mass 0.3
  }
  controller "my_controller"
  linearVelocity -0.004287224908137989 0.0043827759184186 2.4173167242524192e-05
  angularVelocity -0.00023297584153155306 0.0001735906708448121 -0.07168935626769904
}