#VRML_SIM R2025a utf8
EXTERNPROTO "https://raw.githubusercontent.com/cyberbotics/webots/R2025a/projects/objects/backgrounds/protos/TexturedBackground.proto"
EXTERNPROTO "https://raw.githubusercontent.com/cyberbotics/webots/R2025a/projects/objects/backgrounds/protos/TexturedBackgroundLight.proto"

WorldInfo {
}
Viewpoint {
  orientation 0.3219504502661036 0.3905426174928006 -0.8624525328940283 1.5256386099623092
  position -0.5935127217568726 -0.2291043092376283 0.2824277776696549
}
TexturedBackground {
}
TexturedBackgroundLight {
}
RectangleArena {
  floorSize 2 2
  floorAppearance PBRAppearance {
    roughness 1
    roughnessMap ImageTexture {
      url [
        "https://raw.githubusercontent.com/cyberbotics/webots/R2023b/projects/appearances/protos/textures/parquetry/mosaic_parquetry_roughness.jpg"
      ]
    }
    metalness 0
    normalMap ImageTexture {
      url [
        "https://raw.githubusercontent.com/cyberbotics/webots/R2023b/projects/appearances/protos/textures/parquetry/mosaic_parquetry_normal.jpg"
      ]
    }
    occlusionMap ImageTexture {
      url [
        "https://raw.githubusercontent.com/cyberbotics/webots/R2023b/projects/appearances/protos/textures/parquetry/mosaic_parquetry_occlusion.jpg"
      ]
    }
  }
}
Solid {
  translation 0.45 -0.73 0.05
  rotation 0 0 -1 -0.13090030610042527
  children [
    DEF obstacle1 Shape {
      appearance PBRAppearance {
        baseColor 0 0 0
        roughness 1
        metalness 0
      }
      geometry Box {
        size 0.1 0.1 0.1
      }
    }
  ]
  boundingObject USE obstacle1
  locked TRUE
}
Solid {
  translation 0.666748 -0.198009 0.05
  rotation 0 0 -1 -1.3089953071795861
  children [
    DEF obstacle2 Shape {
      appearance PBRAppearance {
        baseColor 0 0 0
        roughness 1
        metalness 0
      }
      geometry Box {
        size 0.2 0.1 0.1
      }
    }
  ]
  name "solid(1)"
  boundingObject USE obstacle2
  locked TRUE
}
Solid {
  translation 0.36358 0.381911 0.05
  rotation 0 0 -1 -1.047195307179586
  children [
    DEF obstacle3 Shape {
      appearance PBRAppearance {
        baseColor 0 0 0
        roughness 1
        metalness 0
      }
      geometry Box {
        size 0.12 0.1 0.1
      }
    }
  ]
  name "solid(3)"
  boundingObject USE obstacle3
  locked TRUE
}
Solid {
  translation -0.380764 0.661551 0.05
  rotation 0 0 1 2.09439
  children [
    DEF obstacle4 Shape {
      appearance PBRAppearance {
        baseColor 0 0 0
        roughness 1
        metalness 0
      }
      geometry Box {
        size 0.12 0.1 0.1
      }
    }
  ]
  name "solid(4)"
  boundingObject USE obstacle4
  locked TRUE
}
Solid {
  translation -0.545793 -0.0756207 0.05
  rotation 0 0 1 1.83259
  children [
    DEF obstacle5 Shape {
      appearance PBRAppearance {
        baseColor 0 0 0
        roughness 1
        metalness 0
      }
      geometry Box {
        size 0.1 0.3 0.1
      }
    }
  ]
  name "solid(5)"
  boundingObject USE obstacle5
  locked TRUE
}
Solid {
  translation -0.356546 -0.527723 0
  rotation 0 0 1 2.8797896938995744
  children [
    Shape {
      appearance PBRAppearance {
        baseColor 1 0 0
        roughness 1
        metalness 0
      }
      geometry Box {
        size 0.03 0.51 0.0005
      }
    }
  ]
  name "solid(6)"
  locked TRUE
}
Solid {
  children [
    Shape {
      appearance PBRAppearance {
        baseColor 0 0 0
        roughness 1
        metalness 0
      }
      geometry Mesh {
        url [
          "../path/outer_path.obj"
        ]
      }
    }
  ]
  name "solid(2)"
  boundingObject Mesh {
    url [
      "../path/outer_path.obj"
    ]
  }
  locked TRUE
}
Solid {
  children [
    Shape {
      appearance PBRAppearance {
        baseColor 0 0 0
        roughness 1
        metalness 0
      }
      geometry Mesh {
        url [
          "../path/inner_path.obj"
        ]
      }
    }
  ]
  name "solid(7)"
  boundingObject Mesh {
    url [
      "../path/inner_path.obj"
    ]
  }
  locked TRUE
}
Robot {
  translation -0.30991533159298706 -0.5228428971341005 0.03831670154955861
  rotation -0.503292108654829 0.6022379124370137 0.6196826205319005 -2.1859645493653757
  children [
    Pose {
      children [
        DEF body Shape {
          appearance PBRAppearance {
            baseColor 0.5 0.6 1
          }
          geometry Box {
            size 0.1 0.04 0.16
          }
        }
      ]
    }
       # Visualized Lidar
    Pose {
      translation 0 0 0.08
      children [
        DEF lidar Lidar {
          translation 0 0 0.08
          rotation 0 1 0 0
          locked TRUE
          horizontalResolution 1
          fieldOfView 6.28319
          numberOfLayers 1
          maxRange 5
          type "rotating"
          noise 0.01
          resolution 512
        }
        Shape {
          appearance PBRAppearance {
            baseColor 0 1 1  # Cyan Lidar
            roughness 1
          }
          geometry Cylinder {
            height 0.02
            radius 0.015
          }
        }
      ]
    }

    # Visualized Right Distance Sensor
    DistanceSensor {
      translation 0.05 0 0.08
      rotation 0 1 0 -0.3
      name "ds_right"
      lookupTable [
        0 0 0
        0.8 800 0
      ]
    }
    Pose {
      translation 0.05 0 0.08
      rotation 0 1 0 -0.3
      children [
        Shape {
          appearance PBRAppearance {
            baseColor 1 1 0  # Yellow
            roughness 1
          }
          geometry Box {
            size 0.01 0.005 0.005
          }
        }
      ]
    }

    # Visualized Left Distance Sensor
    DistanceSensor {
      translation -0.05 0 0.08
      rotation 0 1 0 0.3
      name "ds_left"
      lookupTable [
        0 0 0
        0.8 800 0
      ]
    }
    Pose {
      translation -0.05 0 0.08
      rotation 0 1 0 0.3
      children [
        Shape {
          appearance PBRAppearance {
            baseColor 1 1 0  # Yellow
            roughness 1
          }
          geometry Box {
            size 0.01 0.005 0.005
          }
        }
      ]
    }

    Gyro {
    }
    Accelerometer {
    }
    Compass {
    }
    HingeJoint {
      jointParameters HingeJointParameters {
        position 12.06320894724401
        anchor 0.0598 -0.017 -0.05
      }
      device [
        RotationalMotor {
          name "left_motor"
          maxTorque 0.1
        }
        PositionSensor {
          name "left_encoder"
          resolution 0.01
        }
      ]
      endPoint Solid {
        translation 0.05979999999719965 -0.016998808510702845 -0.049999965913197685
        rotation -0.2415633761637822 -0.9398374272112958 0.2415631298629975 1.6328039014989932
        children [
          DEF wheel Shape {
            appearance PBRAppearance {
              baseColor 1 0 0
              roughness 1
              metalness 0
            }
            geometry Cylinder {
              height 0.02
              radius 0.02
            }
          }
        ]
        boundingObject USE wheel
        physics Physics {
          mass 0.05
        }
      }
    }
    HingeJoint {
      jointParameters HingeJointParameters {
        position 1.180793159991712e-06
        anchor -0.0598 -0.017 -0.05
      }
      device [
        RotationalMotor {
          name "right_motor"
          maxTorque 0.1
        }
        PositionSensor {
          name "right_encoder"
          resolution 0.01
        }
      ]
      endPoint Solid {
        translation -0.059799999997362185 -0.016998808488917147 -0.049999965903599036
        rotation 5.903972353038384e-07 -0.9999999999996514 -5.903965543538335e-07 1.570795307180167
        children [
          USE wheel
        ]
        boundingObject USE wheel
        physics Physics {
          mass 0.05
        }
      }
    }
    BallJoint {
      jointParameters BallJointParameters {
        position 0.2464666855364956
        anchor 0 -0.03 0.05
      }
      endPoint Solid {
        translation -4.660475957366828e-08 -0.029995632888549235 0.05000106544795019
        rotation 0.9155632102565769 -0.1562525383555008 -0.3705794817338566 1.0991068157879824
        children [
          DEF caster Shape {
            appearance PBRAppearance {
              baseColor 0 0 0
              roughness 1
              metalness 0
            }
            geometry Sphere {
              radius 0.01
            }
          }
        ]
        boundingObject USE caster
        physics Physics {
        }
      }
    }
      # Visualized Right Distance Sensor
    DistanceSensor {
      translation 0.05 0 0.08
      rotation 0 1 0 -0.3
      name "ds_right"
      lookupTable [
        0 0 0
        0.8 800 0
      ]
    }
    Pose {
      translation 0.05 0 0.08
      rotation 0 1 0 -0.3
      children [
        Shape {
          appearance PBRAppearance {
            baseColor 1 1 0  # Yellow
            roughness 1
          }
          geometry Box {
            size 0.01 0.005 0.005
          }
        }
      ]
    }

    # Visualized Left Distance Sensor
    DistanceSensor {
      translation -0.05 0 0.08
      rotation 0 1 0 0.3
      name "ds_left"
      lookupTable [
        0 0 0
        0.8 800 0
      ]
    }
    Pose {
      translation -0.05 0 0.08
      rotation 0 1 0 0.3
      children [
        Shape {
          appearance PBRAppearance {
            baseColor 1 1 0  # Yellow
            roughness 1
          }
          geometry Box {
            size 0.01 0.005 0.005
          }
        }
      ]
    }
📌 Notes:
  ]
  boundingObject USE body
  physics Physics {
    mass 0.3
  }
  controller "my_controller"
}