#VRML_SIM R2025a utf8

EXTERNPROTO "https://raw.githubusercontent.com/cyberbotics/webots/R2025a/projects/objects/backgrounds/protos/TexturedBackground.proto"
EXTERNPROTO "https://raw.githubusercontent.com/cyberbotics/webots/R2025a/projects/objects/backgrounds/protos/TexturedBackgroundLight.proto"
EXTERNPROTO "https://raw.githubusercontent.com/cyberbotics/webots/R2025a/projects/objects/floors/protos/RectangleArena.proto"

WorldInfo {
}
Viewpoint {
  orientation 0.5633052163350541 -0.5894327740510409 -0.5790131588523806 4.231035600432828
  position 0.06975029688962248 -0.7364793834161103 3.5777782591323106
}
TexturedBackground {
}
TexturedBackgroundLight {
}
RectangleArena {
  floorSize 2 2
  floorAppearance PBRAppearance {
    roughness 1
    roughnessMap ImageTexture {
      url [
        "https://raw.githubusercontent.com/cyberbotics/webots/R2023b/projects/appearances/protos/textures/parquetry/mosaic_parquetry_roughness.jpg"
      ]
    }
    metalness 0
    normalMap ImageTexture {
      url [
        "https://raw.githubusercontent.com/cyberbotics/webots/R2023b/projects/appearances/protos/textures/parquetry/mosaic_parquetry_normal.jpg"
      ]
    }
    occlusionMap ImageTexture {
      url [
        "https://raw.githubusercontent.com/cyberbotics/webots/R2023b/projects/appearances/protos/textures/parquetry/mosaic_parquetry_occlusion.jpg"
      ]
    }
  }
}
Solid {
  translation 0.45 -0.73 0.05
  rotation 0 0 -1 -0.13090030610042527
  children [
    DEF obstacle1 Shape {
      appearance PBRAppearance {
        baseColor 0 0 0
        roughness 1
        metalness 0
      }
      geometry Box {
        size 0.1 0.1 0.1
      }
    }
  ]
  boundingObject USE obstacle1
  locked TRUE
}
Solid {
  translation 0.666748 -0.198009 0.05
  rotation 0 0 -1 -1.3089953071795861
  children [
    DEF obstacle2 Shape {
      appearance PBRAppearance {
        baseColor 0 0 0
        roughness 1
        metalness 0
      }
      geometry Box {
        size 0.2 0.1 0.1
      }
    }
  ]
  name "solid(1)"
  boundingObject USE obstacle2
  locked TRUE
}
Solid {
  translation 0.36358 0.381911 0.05
  rotation 0 0 -1 -1.047195307179586
  children [
    DEF obstacle3 Shape {
      appearance PBRAppearance {
        baseColor 0 0 0
        roughness 1
        metalness 0
      }
      geometry Box {
        size 0.12 0.1 0.1
      }
    }
  ]
  name "solid(3)"
  boundingObject USE obstacle3
  locked TRUE
}
Solid {
  translation -0.380764 0.661551 0.05
  rotation 0 0 1 2.09439
  children [
    DEF obstacle4 Shape {
      appearance PBRAppearance {
        baseColor 0 0 0
        roughness 1
        metalness 0
      }
      geometry Box {
        size 0.12 0.1 0.1
      }
    }
  ]
  name "solid(4)"
  boundingObject USE obstacle4
  locked TRUE
}
Solid {
  translation -0.545793 -0.0756207 0.05
  rotation 0 0 1 1.83259
  children [
    DEF obstacle5 Shape {
      appearance PBRAppearance {
        baseColor 0 0 0
        roughness 1
        metalness 0
      }
      geometry Box {
        size 0.1 0.3 0.1
      }
    }
  ]
  name "solid(5)"
  boundingObject USE obstacle5
  locked TRUE
}
Solid {
  translation -0.356546 -0.527723 0
  rotation 0 0 1 2.8797896938995744
  children [
    Shape {
      appearance PBRAppearance {
        baseColor 1 0 0
        roughness 1
        metalness 0
      }
      geometry Box {
        size 0.03 0.51 0.0005
      }
    }
  ]
  name "solid(6)"
  locked TRUE
}
Solid {
  children [
    Shape {
      appearance PBRAppearance {
        baseColor 0 0 0
        roughness 1
        metalness 0
      }
      geometry Mesh {
        url [
          "../path/outer_path.obj"
        ]
      }
    }
  ]
  name "solid(2)"
  boundingObject Mesh {
    url [
      "../path/outer_path.obj"
    ]
  }
  locked TRUE
}
Solid {
  children [
    Shape {
      appearance PBRAppearance {
        baseColor 0 0 0
        roughness 1
        metalness 0
      }
      geometry Mesh {
        url [
          "../path/inner_path.obj"
        ]
      }
    }
  ]
  name "solid(7)"
  boundingObject Mesh {
    url [
      "../path/inner_path.obj"
    ]
  }
  locked TRUE
}
Robot {
  translation -0.11504955489160609 -0.5136569652168681 0.03829199187729774
  rotation -0.5293272718588455 0.5913686368258839 0.6083549742092752 -2.144322490675414
  children [
    Lidar {
      translation 2.67257e-05 0.0299963 0.000272275
      rotation 0.5030470370970558 0.6020562948954822 0.6200579781315597 -2.19
      name "lidar(1)"
      type "rotating"
    }
    Pose {
      children [
        DEF body Shape {
          appearance PBRAppearance {
            baseColor 0.5 0.6 1
          }
          geometry Box {
            size 0.1 0.04 0.16
          }
        }
      ]
    }
    Pose {
      translation 0 0 0.08
      children [
        Lidar {
          translation 0 0 0.08
          rotation 0 1 0 0
          horizontalResolution 1
          fieldOfView 6.28319
          numberOfLayers 1
          maxRange 5
          type "rotating"
          noise 0.01
          resolution 512
        }
        Shape {
          appearance PBRAppearance {
            baseColor 0.8 0.8 0.8
          }
          geometry Cylinder {
            height 0.02
            radius 0.02
          }
        }
      ]
    }
    HingeJoint {
      jointParameters HingeJointParameters {
        position 33.40538726436006
        anchor 0.0598 -0.017 -0.05
      }
      device [
        RotationalMotor {
          name "left_motor"
          maxTorque 0.1
        }
        PositionSensor {
          name "left_encoder"
          resolution 0.01
        }
      ]
      endPoint Solid {
        translation 0.059800001312102835 -0.016983315579688667 -0.04999952704347079
        rotation 0.6425687620895989 -0.41738664803093595 -0.6425681069210798 2.3507830525285978
        children [
          DEF wheel Shape {
            appearance PBRAppearance {
              baseColor 1 0 0
              roughness 1
              metalness 0
            }
            geometry Cylinder {
              height 0.02
              radius 0.02
            }
          }
        ]
        boundingObject USE wheel
        physics Physics {
          mass 0.05
        }
        linearVelocity -1.9302828005711324e-09 5.177955310267109e-10 2.85363910279556e-11
        angularVelocity -9.593889228672797e-09 -8.639855017051971e-08 -8.259649069073808e-09
      }
    }
    HingeJoint {
      jointParameters HingeJointParameters {
        position 21.342179670343665
        anchor -0.0598 -0.017 -0.05
      }
      device [
        RotationalMotor {
          name "right_motor"
          maxTorque 0.1
        }
        PositionSensor {
          name "right_encoder"
          resolution 0.01
        }
      ]
      endPoint Solid {
        translation -0.05979999861182306 -0.016983315974141027 -0.049999522749515
        rotation 0.6879158973571751 -0.23139663209377462 -0.6879151959500031 2.686803315890874
        children [
          USE wheel
        ]
        boundingObject USE wheel
        physics Physics {
          mass 0.05
        }
        linearVelocity -9.518378747861013e-10 4.091267867241634e-10 2.8568081233970768e-11
        angularVelocity -9.59331128059782e-09 -8.639342032209162e-08 -8.25964867785095e-09
      }
    }
    BallJoint {
      jointParameters BallJointParameters {
        position -37.28492017059717
        anchor 0 -0.03 0.05
      }
      endPoint Solid {
        translation 8.274006075836837e-07 -0.029958514279020354 0.05000187526024716
        rotation -0.5798090629615064 -0.5188420577030077 0.6281913479714669 -1.2990931585178993
        children [
          DEF caster Shape {
            appearance PBRAppearance {
              baseColor 0 0 0
              roughness 1
              metalness 0
            }
            geometry Sphere {
              radius 0.01
            }
          }
        ]
        boundingObject USE caster
        physics Physics {
        }
        linearVelocity -4.649841801562388e-10 1.2003531378638905e-09 5.269203737082296e-11
        angularVelocity -2.286700085083714e-07 6.825445425537396e-08 4.539294183724364e-11
      }
    }
  ]
  boundingObject USE body
  physics Physics {
    mass 0.3
  }
  controller "two_wheel_controller"
  linearVelocity -2.9840696365487573e-09 1.046903676012415e-09 -1.3502868938532314e-08
  angularVelocity -9.593940964572252e-09 -8.639930939650535e-08 -8.259622522187753e-09
}
