#VRML_SIM R2025a utf8

EXTERNPROTO "https://raw.githubusercontent.com/cyberbotics/webots/R2025a/projects/objects/backgrounds/protos/TexturedBackground.proto"
EXTERNPROTO "https://raw.githubusercontent.com/cyberbotics/webots/R2025a/projects/objects/backgrounds/protos/TexturedBackgroundLight.proto"
EXTERNPROTO "https://raw.githubusercontent.com/cyberbotics/webots/R2025a/projects/objects/floors/protos/RectangleArena.proto"

WorldInfo {
}
Viewpoint {
  orientation 0.31063873544537396 -0.6009155471314888 -0.7364808763685331 5.059164408709177
  position -0.6977207103299642 -1.417718578384647 0.9433249571512239
}
TexturedBackground {
}
TexturedBackgroundLight {
}
RectangleArena {
  floorSize 2 2
  floorAppearance PBRAppearance {
    roughness 1
    roughnessMap ImageTexture {
      url [
        "https://raw.githubusercontent.com/cyberbotics/webots/R2023b/projects/appearances/protos/textures/parquetry/mosaic_parquetry_roughness.jpg"
      ]
    }
    metalness 0
    normalMap ImageTexture {
      url [
        "https://raw.githubusercontent.com/cyberbotics/webots/R2023b/projects/appearances/protos/textures/parquetry/mosaic_parquetry_normal.jpg"
      ]
    }
    occlusionMap ImageTexture {
      url [
        "https://raw.githubusercontent.com/cyberbotics/webots/R2023b/projects/appearances/protos/textures/parquetry/mosaic_parquetry_occlusion.jpg"
      ]
    }
  }
}
Solid {
  translation 0.45 -0.73 0.05
  rotation 0 0 -1 -0.13090030610042527
  children [
    DEF obstacle1 Shape {
      appearance PBRAppearance {
        baseColor 0 0 0
        roughness 1
        metalness 0
      }
      geometry Box {
        size 0.1 0.1 0.1
      }
    }
  ]
  boundingObject USE obstacle1
  locked TRUE
}
Solid {
  translation 0.666748 -0.198009 0.05
  rotation 0 0 -1 -1.3089953071795861
  children [
    DEF obstacle2 Shape {
      appearance PBRAppearance {
        baseColor 0 0 0
        roughness 1
        metalness 0
      }
      geometry Box {
        size 0.2 0.1 0.1
      }
    }
  ]
  name "solid(1)"
  boundingObject USE obstacle2
  locked TRUE
}
Solid {
  translation 0.36358 0.381911 0.05
  rotation 0 0 -1 -1.047195307179586
  children [
    DEF obstacle3 Shape {
      appearance PBRAppearance {
        baseColor 0 0 0
        roughness 1
        metalness 0
      }
      geometry Box {
        size 0.12 0.1 0.1
      }
    }
  ]
  name "solid(3)"
  boundingObject USE obstacle3
  locked TRUE
}
Solid {
  translation -0.380764 0.661551 0.05
  rotation 0 0 1 2.09439
  children [
    DEF obstacle4 Shape {
      appearance PBRAppearance {
        baseColor 0 0 0
        roughness 1
        metalness 0
      }
      geometry Box {
        size 0.12 0.1 0.1
      }
    }
  ]
  name "solid(4)"
  boundingObject USE obstacle4
  locked TRUE
}
Solid {
  translation -0.545793 -0.0756207 0.05
  rotation 0 0 1 1.83259
  children [
    DEF obstacle5 Shape {
      appearance PBRAppearance {
        baseColor 0 0 0
        roughness 1
        metalness 0
      }
      geometry Box {
        size 0.1 0.3 0.1
      }
    }
  ]
  name "solid(5)"
  boundingObject USE obstacle5
  locked TRUE
}
Solid {
  translation -0.356546 -0.527723 0
  rotation 0 0 1 2.8797896938995744
  children [
    Shape {
      appearance PBRAppearance {
        baseColor 1 0 0
        roughness 1
        metalness 0
      }
      geometry Box {
        size 0.03 0.51 0.0005
      }
    }
  ]
  name "solid(6)"
  locked TRUE
}
Solid {
  children [
    Shape {
      appearance PBRAppearance {
        baseColor 0 0 0
        roughness 1
        metalness 0
      }
      geometry Mesh {
        url [
          "../path/outer_path.obj"
        ]
      }
    }
  ]
  name "solid(2)"
  boundingObject Mesh {
    url [
      "../path/outer_path.obj"
    ]
  }
  locked TRUE
}
Solid {
  children [
    Shape {
      appearance PBRAppearance {
        baseColor 0 0 0
        roughness 1
        metalness 0
      }
      geometry Mesh {
        url [
          "../path/inner_path.obj"
        ]
      }
    }
  ]
  name "solid(7)"
  boundingObject Mesh {
    url [
      "../path/inner_path.obj"
    ]
  }
  locked TRUE
}
Robot {
  translation -0.11005529955591133 -0.5142096234083903 0.038285113953560546
  rotation -0.5293544420267263 0.5913991000660003 0.6083017171993668 -2.144396181569272
  children [
    Gyro {
      translation 0.02 0.02 0.03
      children [
        Shape {
          appearance PBRAppearance {
          }
          geometry Box {
            size 0.01 0.01 0.01
          }
        }
      ]
    }
    Accelerometer {
      translation 0 0.04 -0.05
      children [
        Shape {
          appearance PBRAppearance {
            baseColor 0 1 0.7
          }
          geometry Box {
            size 0.05 0.05 0.05
          }
        }
      ]
    }
    InertialUnit {
      translation -0.03 0.02 0
      children [
        Shape {
          appearance PBRAppearance {
            metalness 0
          }
          geometry Box {
            size 0.01 0.01 0.01
          }
        }
      ]
      name "inertial_unit"
    }
    Lidar {
      translation 2.67257e-05 0.0299963 0.000272275
      rotation 0.5030470370970558 0.6020562948954822 0.6200579781315597 -2.19
      name "lidar(1)"
      type "rotating"
    }
    Pose {
      children [
        DEF body Shape {
          appearance PBRAppearance {
            baseColor 0.5 0.6 1
          }
          geometry Box {
            size 0.1 0.04 0.16
          }
        }
      ]
    }
    Pose {
      translation 0 0 0.08
      children [
        Lidar {
          translation 0 0 0.08
          rotation 0 1 0 0
          horizontalResolution 1
          fieldOfView 6.28319
          numberOfLayers 1
          maxRange 5
          type "rotating"
          noise 0.01
          resolution 512
        }
        Shape {
          appearance PBRAppearance {
            baseColor 0.8 0.8 0.8
          }
          geometry Cylinder {
            height 0.02
            radius 0.02
          }
        }
      ]
    }
    HingeJoint {
      jointParameters HingeJointParameters {
        position 33.40538725587606
        anchor 0.0598 -0.017 -0.05
      }
      device [
        RotationalMotor {
          name "left_wheel_motor"
          maxTorque 0.1
        }
        PositionSensor {
          name "left_wheel_sensor"
          resolution 0.01
        }
      ]
      endPoint Solid {
        translation 0.059800001312102835 -0.01698331557968466 -0.04999952704361234
        rotation 0.6425687610498488 -0.41738665123117347 -0.642568105882084 2.3507830470759092
        children [
          DEF wheel Shape {
            appearance PBRAppearance {
              baseColor 1 0 0
              roughness 1
              metalness 0
            }
            geometry Cylinder {
              height 0.02
              radius 0.02
            }
          }
        ]
        boundingObject USE wheel
        physics Physics {
          mass 0.05
        }
        linearVelocity -3.763577726591298e-09 7.206490109951514e-10 9.24821179637526e-09
        angularVelocity -1.9806915067207273e-08 -1.783483983486604e-07 -8.237683738657278e-09
      }
    }
    HingeJoint {
      jointParameters HingeJointParameters {
        position 21.3421796612729
        anchor -0.0598 -0.017 -0.05
      }
      device [
        RotationalMotor {
          name "right_wheel_motor"
          maxTorque 0.1
        }
        PositionSensor {
          name "right_wheel_sensor"
          resolution 0.01
        }
      ]
      endPoint Solid {
        translation -0.05979999861182306 -0.0169833159741367 -0.04999952274966634
        rotation 0.6879158968045901 -0.23139663537917995 -0.6879151953974644 2.686803309647868
        children [
          USE wheel
        ]
        boundingObject USE wheel
        physics Physics {
          mass 0.05
        }
        linearVelocity -2.7877431072865123e-09 6.12269519999301e-10 9.248112107230027e-09
        angularVelocity -1.9806915011953917e-08 -1.7834841902434536e-07 -8.237683014868534e-09
      }
    }
    BallJoint {
      jointParameters BallJointParameters {
        position -37.28492869001756
        anchor 0 -0.03 0.05
      }
      endPoint Solid {
        translation 8.240813332838215e-07 -0.02994459204855271 0.05000227340708921
        rotation -0.5798255766554165 -0.5189246923384941 0.6281078445120812 -1.2991827384516377
        children [
          DEF caster Shape {
            appearance PBRAppearance {
              baseColor 0 0 0
              roughness 1
              metalness 0
            }
            geometry Sphere {
              radius 0.01
            }
          }
        ]
        boundingObject USE caster
        physics Physics {
        }
        linearVelocity -1.3646967763838263e-09 1.3005497428289282e-09 -7.078642499061416e-12
        angularVelocity -2.3818132072397338e-07 -1.9927733018568407e-08 7.21372469559228e-11
      }
    }
  ]
  boundingObject USE body
  physics Physics {
    mass 0.3
  }
  controller "wall_following_controller"
  linearVelocity -6.508441309031341e-09 1.4365131299194164e-09 -8.862520436045549e-09
  angularVelocity -1.9806913179523874e-08 -1.7834841384027243e-07 -8.237657409254587e-09
}
